<robot name="simple_agv">
    <link name="base_link">
        <visual>
            <geometry>
                <box size="0.5 0.3 0.1"/>
            </geometry>
        </visual>
    </link>

    <link name="left_wheel">
        <visual>
            <geometry>
                <cylinder radius="0.1" length="0.05"/>
            </geometry>
        </visual>
    </link>

    <link name="right_wheel">
        <visual>
            <geometry>
                <cylinder radius="0.1" length="0.05"/>
            </geometry>
        </visual>
    </link>

    <joint name="left_wheel_joint" type="revolute">
        <parent link="base_link"/>
        <child link="left_wheel"/>
        <origin xyz="-0.2 0 0" rpy="0 0 0"/>
        <axis xyz="0 0 1"/>
        <limit effort="10" lower="-1.57" upper="1.57" velocity="1.0"/>  <!-- Added limits -->
    </joint>

    <joint name="right_wheel_joint" type="revolute">
        <parent link="base_link"/>
        <child link="right_wheel"/>
        <origin xyz="0.2 0 0" rpy="0 0 0"/>
        <axis xyz="0 0 1"/>
        <limit effort="10" lower="-1.57" upper="1.57" velocity="1.0"/>  <!-- Added limits -->
    </joint>
</robot>
